{
 "cells": [
  {
   "cell_type": "code",
   "execution_count": 1,
   "source": [
    "import tensorflow as tf\r\n",
    "import onnx\r\n",
    "import keras as keras\r\n",
    "import torch\r\n",
    "import torch.nn as nn\r\n",
    "import torch.nn.functional as F\r\n",
    "from HelperFunctions import *\r\n",
    "from torch.autograd import Variable"
   ],
   "outputs": [
    {
     "output_type": "stream",
     "name": "stderr",
     "text": [
      "Using TensorFlow backend.\n"
     ]
    }
   ],
   "metadata": {}
  },
  {
   "cell_type": "code",
   "execution_count": 2,
   "source": [
    "device = torch.device(0 if torch.cuda.is_available() else 'cpu')\r\n",
    "device_name = torch.cuda.get_device_name(0)"
   ],
   "outputs": [],
   "metadata": {}
  },
  {
   "cell_type": "code",
   "execution_count": 3,
   "source": [
    "model = AlexNet().to(device)\r\n",
    "model_file = \"Models/AlexNetv2.1s=64.pt\"\r\n",
    "check_point = torch.load(model_file)\r\n",
    "model.load_state_dict(check_point['model_state_dict'])\r\n",
    "print(model)"
   ],
   "outputs": [
    {
     "output_type": "stream",
     "name": "stdout",
     "text": [
      "AlexNet(\n",
      "  (features): Sequential(\n",
      "    (0): Conv2d(3, 64, kernel_size=(11, 11), stride=(4, 4), padding=(2, 2))\n",
      "    (1): ReLU(inplace=True)\n",
      "    (2): MaxPool2d(kernel_size=3, stride=2, padding=0, dilation=1, ceil_mode=False)\n",
      "    (3): Conv2d(64, 192, kernel_size=(5, 5), stride=(1, 1), padding=(2, 2))\n",
      "    (4): ReLU(inplace=True)\n",
      "    (5): MaxPool2d(kernel_size=3, stride=2, padding=0, dilation=1, ceil_mode=False)\n",
      "    (6): Conv2d(192, 384, kernel_size=(3, 3), stride=(1, 1), padding=(1, 1))\n",
      "    (7): ReLU(inplace=True)\n",
      "    (8): Conv2d(384, 256, kernel_size=(3, 3), stride=(1, 1), padding=(1, 1))\n",
      "    (9): ReLU(inplace=True)\n",
      "    (10): Conv2d(256, 256, kernel_size=(3, 3), stride=(1, 1), padding=(1, 1))\n",
      "    (11): ReLU(inplace=True)\n",
      "    (12): MaxPool2d(kernel_size=3, stride=2, padding=0, dilation=1, ceil_mode=False)\n",
      "  )\n",
      "  (avgpool): AdaptiveAvgPool2d(output_size=(6, 6))\n",
      "  (classifier): Sequential(\n",
      "    (0): Dropout(p=0.5, inplace=False)\n",
      "    (1): Linear(in_features=9216, out_features=4096, bias=True)\n",
      "    (2): ReLU(inplace=True)\n",
      "    (3): Dropout(p=0.5, inplace=False)\n",
      "    (4): Linear(in_features=4096, out_features=4096, bias=True)\n",
      "    (5): ReLU(inplace=True)\n",
      "    (6): Linear(in_features=4096, out_features=1000, bias=True)\n",
      "    (7): ReLU(inplace=True)\n",
      "    (8): Linear(in_features=1000, out_features=5, bias=True)\n",
      "  )\n",
      ")\n"
     ]
    }
   ],
   "metadata": {}
  },
  {
   "cell_type": "code",
   "execution_count": 4,
   "source": [
    "# Export the trained model to ONNX\r\n",
    "dummy_input = Variable(torch.randn(1, 3, 64, 64).to(device))\r\n",
    "torch.onnx.export(model, dummy_input, \"Models/AlexNet.onnx\", input_names=[\"input\"], output_names=[\"output\"])"
   ],
   "outputs": [
    {
     "output_type": "stream",
     "name": "stderr",
     "text": [
      "C:\\ProgramData\\Anaconda3\\envs\\tf1\\lib\\site-packages\\torch\\nn\\functional.py:718: UserWarning: Named tensors and all their associated APIs are an experimental feature and subject to change. Please do not use them for anything important until they are released as stable. (Triggered internally at  ..\\c10/core/TensorImpl.h:1156.)\n",
      "  return torch.max_pool2d(input, kernel_size, stride, padding, dilation, ceil_mode)\n",
      "ERROR:root:Internal Python error in the inspect module.\n",
      "Below is the traceback from this internal error.\n",
      "\n",
      "ERROR:root:Internal Python error in the inspect module.\n",
      "Below is the traceback from this internal error.\n",
      "\n",
      "ERROR:root:Internal Python error in the inspect module.\n",
      "Below is the traceback from this internal error.\n",
      "\n"
     ]
    },
    {
     "output_type": "stream",
     "name": "stdout",
     "text": [
      "Traceback (most recent call last):\n",
      "  File \"C:\\ProgramData\\Anaconda3\\envs\\tf1\\lib\\site-packages\\IPython\\core\\interactiveshell.py\", line 3441, in run_code\n",
      "    exec(code_obj, self.user_global_ns, self.user_ns)\n",
      "  File \"C:\\Users\\zarre\\AppData\\Local\\Temp/ipykernel_35636/2681859144.py\", line 3, in <module>\n",
      "    torch.onnx.export(model, dummy_input, \"Models/AlexNet.onnx\", input_names=[\"input\"], output_names=[\"output\"])\n",
      "  File \"C:\\ProgramData\\Anaconda3\\envs\\tf1\\lib\\site-packages\\torch\\onnx\\__init__.py\", line 280, in export\n",
      "    custom_opsets, enable_onnx_checker, use_external_data_format)\n",
      "  File \"C:\\ProgramData\\Anaconda3\\envs\\tf1\\lib\\site-packages\\torch\\onnx\\utils.py\", line 94, in export\n",
      "    use_external_data_format=use_external_data_format)\n",
      "  File \"C:\\ProgramData\\Anaconda3\\envs\\tf1\\lib\\site-packages\\torch\\onnx\\utils.py\", line 695, in _export\n",
      "    dynamic_axes=dynamic_axes)\n",
      "  File \"C:\\ProgramData\\Anaconda3\\envs\\tf1\\lib\\site-packages\\torch\\onnx\\utils.py\", line 467, in _model_to_graph\n",
      "    module=module)\n",
      "  File \"C:\\ProgramData\\Anaconda3\\envs\\tf1\\lib\\site-packages\\torch\\onnx\\utils.py\", line 200, in _optimize_graph\n",
      "    graph = torch._C._jit_pass_onnx(graph, operator_export_type)\n",
      "  File \"C:\\ProgramData\\Anaconda3\\envs\\tf1\\lib\\site-packages\\torch\\onnx\\__init__.py\", line 313, in _run_symbolic_function\n",
      "    return utils._run_symbolic_function(*args, **kwargs)\n",
      "  File \"C:\\ProgramData\\Anaconda3\\envs\\tf1\\lib\\site-packages\\torch\\onnx\\utils.py\", line 994, in _run_symbolic_function\n",
      "    return symbolic_fn(g, *inputs, **attrs)\n",
      "  File \"C:\\ProgramData\\Anaconda3\\envs\\tf1\\lib\\site-packages\\torch\\onnx\\symbolic_opset9.py\", line 982, in symbolic_fn\n",
      "    return sym_help._onnx_unsupported(name + ', since output size is not factor of input size')\n",
      "  File \"C:\\ProgramData\\Anaconda3\\envs\\tf1\\lib\\site-packages\\torch\\onnx\\symbolic_helper.py\", line 248, in _onnx_unsupported\n",
      "    'Please feel free to request support or submit a pull request on PyTorch GitHub.'.format(op_name))\n",
      "RuntimeError: Unsupported: ONNX export of operator adaptive_avg_pool2d, since output size is not factor of input size. Please feel free to request support or submit a pull request on PyTorch GitHub.\n",
      "\n",
      "During handling of the above exception, another exception occurred:\n",
      "\n",
      "Traceback (most recent call last):\n",
      "  File \"C:\\ProgramData\\Anaconda3\\envs\\tf1\\lib\\site-packages\\IPython\\core\\interactiveshell.py\", line 2061, in showtraceback\n",
      "    stb = value._render_traceback_()\n",
      "AttributeError: 'RuntimeError' object has no attribute '_render_traceback_'\n",
      "\n",
      "During handling of the above exception, another exception occurred:\n",
      "\n",
      "Traceback (most recent call last):\n",
      "  File \"C:\\ProgramData\\Anaconda3\\envs\\tf1\\lib\\site-packages\\IPython\\core\\ultratb.py\", line 1101, in get_records\n",
      "    return _fixed_getinnerframes(etb, number_of_lines_of_context, tb_offset)\n",
      "  File \"C:\\ProgramData\\Anaconda3\\envs\\tf1\\lib\\site-packages\\IPython\\core\\ultratb.py\", line 248, in wrapped\n",
      "    return f(*args, **kwargs)\n",
      "  File \"C:\\ProgramData\\Anaconda3\\envs\\tf1\\lib\\site-packages\\IPython\\core\\ultratb.py\", line 281, in _fixed_getinnerframes\n",
      "    records = fix_frame_records_filenames(inspect.getinnerframes(etb, context))\n",
      "  File \"C:\\ProgramData\\Anaconda3\\envs\\tf1\\lib\\inspect.py\", line 1502, in getinnerframes\n",
      "    frameinfo = (tb.tb_frame,) + getframeinfo(tb, context)\n",
      "  File \"C:\\ProgramData\\Anaconda3\\envs\\tf1\\lib\\inspect.py\", line 1460, in getframeinfo\n",
      "    filename = getsourcefile(frame) or getfile(frame)\n",
      "  File \"C:\\ProgramData\\Anaconda3\\envs\\tf1\\lib\\inspect.py\", line 696, in getsourcefile\n",
      "    if getattr(getmodule(object, filename), '__loader__', None) is not None:\n",
      "  File \"C:\\ProgramData\\Anaconda3\\envs\\tf1\\lib\\inspect.py\", line 733, in getmodule\n",
      "    if ismodule(module) and hasattr(module, '__file__'):\n",
      "  File \"C:\\ProgramData\\Anaconda3\\envs\\tf1\\lib\\site-packages\\tensorflow\\__init__.py\", line 50, in __getattr__\n",
      "    module = self._load()\n",
      "  File \"C:\\ProgramData\\Anaconda3\\envs\\tf1\\lib\\site-packages\\tensorflow\\__init__.py\", line 44, in _load\n",
      "    module = _importlib.import_module(self.__name__)\n",
      "  File \"C:\\ProgramData\\Anaconda3\\envs\\tf1\\lib\\importlib\\__init__.py\", line 127, in import_module\n",
      "    return _bootstrap._gcd_import(name[level:], package, level)\n",
      "  File \"<frozen importlib._bootstrap>\", line 1006, in _gcd_import\n",
      "  File \"<frozen importlib._bootstrap>\", line 983, in _find_and_load\n",
      "  File \"<frozen importlib._bootstrap>\", line 967, in _find_and_load_unlocked\n",
      "  File \"<frozen importlib._bootstrap>\", line 677, in _load_unlocked\n",
      "  File \"<frozen importlib._bootstrap_external>\", line 728, in exec_module\n",
      "  File \"<frozen importlib._bootstrap>\", line 219, in _call_with_frames_removed\n",
      "  File \"C:\\ProgramData\\Anaconda3\\envs\\tf1\\lib\\site-packages\\tensorflow_core\\contrib\\__init__.py\", line 39, in <module>\n",
      "    from tensorflow.contrib import compiler\n",
      "  File \"C:\\ProgramData\\Anaconda3\\envs\\tf1\\lib\\site-packages\\tensorflow_core\\contrib\\compiler\\__init__.py\", line 21, in <module>\n",
      "    from tensorflow.contrib.compiler import jit\n",
      "  File \"C:\\ProgramData\\Anaconda3\\envs\\tf1\\lib\\site-packages\\tensorflow_core\\contrib\\compiler\\__init__.py\", line 22, in <module>\n",
      "    from tensorflow.contrib.compiler import xla\n",
      "  File \"C:\\ProgramData\\Anaconda3\\envs\\tf1\\lib\\site-packages\\tensorflow_core\\contrib\\compiler\\xla.py\", line 22, in <module>\n",
      "    from tensorflow.python.estimator import model_fn as model_fn_lib\n",
      "  File \"C:\\ProgramData\\Anaconda3\\envs\\tf1\\lib\\site-packages\\tensorflow_core\\python\\estimator\\model_fn.py\", line 26, in <module>\n",
      "    from tensorflow_estimator.python.estimator import model_fn\n",
      "  File \"C:\\ProgramData\\Anaconda3\\envs\\tf1\\lib\\site-packages\\tensorflow_estimator\\python\\estimator\\model_fn.py\", line 29, in <module>\n",
      "    from tensorflow.python.types import core\n",
      "ModuleNotFoundError: No module named 'tensorflow.python.types'\n",
      "Traceback (most recent call last):\n",
      "  File \"C:\\ProgramData\\Anaconda3\\envs\\tf1\\lib\\site-packages\\IPython\\core\\interactiveshell.py\", line 3441, in run_code\n",
      "    exec(code_obj, self.user_global_ns, self.user_ns)\n",
      "  File \"C:\\Users\\zarre\\AppData\\Local\\Temp/ipykernel_35636/2681859144.py\", line 3, in <module>\n",
      "    torch.onnx.export(model, dummy_input, \"Models/AlexNet.onnx\", input_names=[\"input\"], output_names=[\"output\"])\n",
      "  File \"C:\\ProgramData\\Anaconda3\\envs\\tf1\\lib\\site-packages\\torch\\onnx\\__init__.py\", line 280, in export\n",
      "    custom_opsets, enable_onnx_checker, use_external_data_format)\n",
      "  File \"C:\\ProgramData\\Anaconda3\\envs\\tf1\\lib\\site-packages\\torch\\onnx\\utils.py\", line 94, in export\n",
      "    use_external_data_format=use_external_data_format)\n",
      "  File \"C:\\ProgramData\\Anaconda3\\envs\\tf1\\lib\\site-packages\\torch\\onnx\\utils.py\", line 695, in _export\n",
      "    dynamic_axes=dynamic_axes)\n",
      "  File \"C:\\ProgramData\\Anaconda3\\envs\\tf1\\lib\\site-packages\\torch\\onnx\\utils.py\", line 467, in _model_to_graph\n",
      "    module=module)\n",
      "  File \"C:\\ProgramData\\Anaconda3\\envs\\tf1\\lib\\site-packages\\torch\\onnx\\utils.py\", line 200, in _optimize_graph\n",
      "    graph = torch._C._jit_pass_onnx(graph, operator_export_type)\n",
      "  File \"C:\\ProgramData\\Anaconda3\\envs\\tf1\\lib\\site-packages\\torch\\onnx\\__init__.py\", line 313, in _run_symbolic_function\n",
      "    return utils._run_symbolic_function(*args, **kwargs)\n",
      "  File \"C:\\ProgramData\\Anaconda3\\envs\\tf1\\lib\\site-packages\\torch\\onnx\\utils.py\", line 994, in _run_symbolic_function\n",
      "    return symbolic_fn(g, *inputs, **attrs)\n",
      "  File \"C:\\ProgramData\\Anaconda3\\envs\\tf1\\lib\\site-packages\\torch\\onnx\\symbolic_opset9.py\", line 982, in symbolic_fn\n",
      "    return sym_help._onnx_unsupported(name + ', since output size is not factor of input size')\n",
      "  File \"C:\\ProgramData\\Anaconda3\\envs\\tf1\\lib\\site-packages\\torch\\onnx\\symbolic_helper.py\", line 248, in _onnx_unsupported\n",
      "    'Please feel free to request support or submit a pull request on PyTorch GitHub.'.format(op_name))\n",
      "RuntimeError: Unsupported: ONNX export of operator adaptive_avg_pool2d, since output size is not factor of input size. Please feel free to request support or submit a pull request on PyTorch GitHub.\n",
      "\n",
      "During handling of the above exception, another exception occurred:\n",
      "\n",
      "Traceback (most recent call last):\n",
      "  File \"C:\\ProgramData\\Anaconda3\\envs\\tf1\\lib\\site-packages\\IPython\\core\\interactiveshell.py\", line 2061, in showtraceback\n",
      "    stb = value._render_traceback_()\n",
      "AttributeError: 'RuntimeError' object has no attribute '_render_traceback_'\n",
      "\n",
      "During handling of the above exception, another exception occurred:\n",
      "\n",
      "Traceback (most recent call last):\n",
      "  File \"C:\\ProgramData\\Anaconda3\\envs\\tf1\\lib\\site-packages\\IPython\\core\\interactiveshell.py\", line 3361, in run_ast_nodes\n",
      "    if (await self.run_code(code, result,  async_=asy)):\n",
      "  File \"C:\\ProgramData\\Anaconda3\\envs\\tf1\\lib\\site-packages\\IPython\\core\\interactiveshell.py\", line 3458, in run_code\n",
      "    self.showtraceback(running_compiled_code=True)\n",
      "  File \"C:\\ProgramData\\Anaconda3\\envs\\tf1\\lib\\site-packages\\IPython\\core\\interactiveshell.py\", line 2064, in showtraceback\n",
      "    value, tb, tb_offset=tb_offset)\n",
      "  File \"C:\\ProgramData\\Anaconda3\\envs\\tf1\\lib\\site-packages\\IPython\\core\\ultratb.py\", line 1368, in structured_traceback\n",
      "    self, etype, value, tb, tb_offset, number_of_lines_of_context)\n",
      "  File \"C:\\ProgramData\\Anaconda3\\envs\\tf1\\lib\\site-packages\\IPython\\core\\ultratb.py\", line 1268, in structured_traceback\n",
      "    self, etype, value, tb, tb_offset, number_of_lines_of_context\n",
      "  File \"C:\\ProgramData\\Anaconda3\\envs\\tf1\\lib\\site-packages\\IPython\\core\\ultratb.py\", line 1125, in structured_traceback\n",
      "    tb_offset)\n",
      "  File \"C:\\ProgramData\\Anaconda3\\envs\\tf1\\lib\\site-packages\\IPython\\core\\ultratb.py\", line 1082, in format_exception_as_a_whole\n",
      "    last_unique, recursion_repeat = find_recursion(orig_etype, evalue, records)\n",
      "  File \"C:\\ProgramData\\Anaconda3\\envs\\tf1\\lib\\site-packages\\IPython\\core\\ultratb.py\", line 382, in find_recursion\n",
      "    return len(records), 0\n",
      "TypeError: object of type 'NoneType' has no len()\n",
      "\n",
      "During handling of the above exception, another exception occurred:\n",
      "\n",
      "Traceback (most recent call last):\n",
      "  File \"C:\\ProgramData\\Anaconda3\\envs\\tf1\\lib\\site-packages\\IPython\\core\\interactiveshell.py\", line 2061, in showtraceback\n",
      "    stb = value._render_traceback_()\n",
      "AttributeError: 'TypeError' object has no attribute '_render_traceback_'\n",
      "\n",
      "During handling of the above exception, another exception occurred:\n",
      "\n",
      "Traceback (most recent call last):\n",
      "  File \"C:\\ProgramData\\Anaconda3\\envs\\tf1\\lib\\site-packages\\IPython\\core\\ultratb.py\", line 1101, in get_records\n",
      "    return _fixed_getinnerframes(etb, number_of_lines_of_context, tb_offset)\n",
      "  File \"C:\\ProgramData\\Anaconda3\\envs\\tf1\\lib\\site-packages\\IPython\\core\\ultratb.py\", line 248, in wrapped\n",
      "    return f(*args, **kwargs)\n",
      "  File \"C:\\ProgramData\\Anaconda3\\envs\\tf1\\lib\\site-packages\\IPython\\core\\ultratb.py\", line 281, in _fixed_getinnerframes\n",
      "    records = fix_frame_records_filenames(inspect.getinnerframes(etb, context))\n",
      "  File \"C:\\ProgramData\\Anaconda3\\envs\\tf1\\lib\\inspect.py\", line 1502, in getinnerframes\n",
      "    frameinfo = (tb.tb_frame,) + getframeinfo(tb, context)\n",
      "  File \"C:\\ProgramData\\Anaconda3\\envs\\tf1\\lib\\inspect.py\", line 1460, in getframeinfo\n",
      "    filename = getsourcefile(frame) or getfile(frame)\n",
      "  File \"C:\\ProgramData\\Anaconda3\\envs\\tf1\\lib\\inspect.py\", line 696, in getsourcefile\n",
      "    if getattr(getmodule(object, filename), '__loader__', None) is not None:\n",
      "  File \"C:\\ProgramData\\Anaconda3\\envs\\tf1\\lib\\inspect.py\", line 733, in getmodule\n",
      "    if ismodule(module) and hasattr(module, '__file__'):\n",
      "  File \"C:\\ProgramData\\Anaconda3\\envs\\tf1\\lib\\site-packages\\tensorflow\\__init__.py\", line 50, in __getattr__\n",
      "    module = self._load()\n",
      "  File \"C:\\ProgramData\\Anaconda3\\envs\\tf1\\lib\\site-packages\\tensorflow\\__init__.py\", line 44, in _load\n",
      "    module = _importlib.import_module(self.__name__)\n",
      "  File \"C:\\ProgramData\\Anaconda3\\envs\\tf1\\lib\\importlib\\__init__.py\", line 127, in import_module\n",
      "    return _bootstrap._gcd_import(name[level:], package, level)\n",
      "  File \"<frozen importlib._bootstrap>\", line 1006, in _gcd_import\n",
      "  File \"<frozen importlib._bootstrap>\", line 983, in _find_and_load\n",
      "  File \"<frozen importlib._bootstrap>\", line 965, in _find_and_load_unlocked\n",
      "ModuleNotFoundError: No module named 'tensorflow_core.estimator'\n",
      "Traceback (most recent call last):\n",
      "  File \"C:\\ProgramData\\Anaconda3\\envs\\tf1\\lib\\site-packages\\IPython\\core\\interactiveshell.py\", line 3441, in run_code\n",
      "    exec(code_obj, self.user_global_ns, self.user_ns)\n",
      "  File \"C:\\Users\\zarre\\AppData\\Local\\Temp/ipykernel_35636/2681859144.py\", line 3, in <module>\n",
      "    torch.onnx.export(model, dummy_input, \"Models/AlexNet.onnx\", input_names=[\"input\"], output_names=[\"output\"])\n",
      "  File \"C:\\ProgramData\\Anaconda3\\envs\\tf1\\lib\\site-packages\\torch\\onnx\\__init__.py\", line 280, in export\n",
      "    custom_opsets, enable_onnx_checker, use_external_data_format)\n",
      "  File \"C:\\ProgramData\\Anaconda3\\envs\\tf1\\lib\\site-packages\\torch\\onnx\\utils.py\", line 94, in export\n",
      "    use_external_data_format=use_external_data_format)\n",
      "  File \"C:\\ProgramData\\Anaconda3\\envs\\tf1\\lib\\site-packages\\torch\\onnx\\utils.py\", line 695, in _export\n",
      "    dynamic_axes=dynamic_axes)\n",
      "  File \"C:\\ProgramData\\Anaconda3\\envs\\tf1\\lib\\site-packages\\torch\\onnx\\utils.py\", line 467, in _model_to_graph\n",
      "    module=module)\n",
      "  File \"C:\\ProgramData\\Anaconda3\\envs\\tf1\\lib\\site-packages\\torch\\onnx\\utils.py\", line 200, in _optimize_graph\n",
      "    graph = torch._C._jit_pass_onnx(graph, operator_export_type)\n",
      "  File \"C:\\ProgramData\\Anaconda3\\envs\\tf1\\lib\\site-packages\\torch\\onnx\\__init__.py\", line 313, in _run_symbolic_function\n",
      "    return utils._run_symbolic_function(*args, **kwargs)\n",
      "  File \"C:\\ProgramData\\Anaconda3\\envs\\tf1\\lib\\site-packages\\torch\\onnx\\utils.py\", line 994, in _run_symbolic_function\n",
      "    return symbolic_fn(g, *inputs, **attrs)\n",
      "  File \"C:\\ProgramData\\Anaconda3\\envs\\tf1\\lib\\site-packages\\torch\\onnx\\symbolic_opset9.py\", line 982, in symbolic_fn\n",
      "    return sym_help._onnx_unsupported(name + ', since output size is not factor of input size')\n",
      "  File \"C:\\ProgramData\\Anaconda3\\envs\\tf1\\lib\\site-packages\\torch\\onnx\\symbolic_helper.py\", line 248, in _onnx_unsupported\n",
      "    'Please feel free to request support or submit a pull request on PyTorch GitHub.'.format(op_name))\n",
      "RuntimeError: Unsupported: ONNX export of operator adaptive_avg_pool2d, since output size is not factor of input size. Please feel free to request support or submit a pull request on PyTorch GitHub.\n",
      "\n",
      "During handling of the above exception, another exception occurred:\n",
      "\n",
      "Traceback (most recent call last):\n",
      "  File \"C:\\ProgramData\\Anaconda3\\envs\\tf1\\lib\\site-packages\\IPython\\core\\interactiveshell.py\", line 2061, in showtraceback\n",
      "    stb = value._render_traceback_()\n",
      "AttributeError: 'RuntimeError' object has no attribute '_render_traceback_'\n",
      "\n",
      "During handling of the above exception, another exception occurred:\n",
      "\n",
      "Traceback (most recent call last):\n",
      "  File \"C:\\ProgramData\\Anaconda3\\envs\\tf1\\lib\\site-packages\\IPython\\core\\interactiveshell.py\", line 3361, in run_ast_nodes\n",
      "    if (await self.run_code(code, result,  async_=asy)):\n",
      "  File \"C:\\ProgramData\\Anaconda3\\envs\\tf1\\lib\\site-packages\\IPython\\core\\interactiveshell.py\", line 3458, in run_code\n",
      "    self.showtraceback(running_compiled_code=True)\n",
      "  File \"C:\\ProgramData\\Anaconda3\\envs\\tf1\\lib\\site-packages\\IPython\\core\\interactiveshell.py\", line 2064, in showtraceback\n",
      "    value, tb, tb_offset=tb_offset)\n",
      "  File \"C:\\ProgramData\\Anaconda3\\envs\\tf1\\lib\\site-packages\\IPython\\core\\ultratb.py\", line 1368, in structured_traceback\n",
      "    self, etype, value, tb, tb_offset, number_of_lines_of_context)\n",
      "  File \"C:\\ProgramData\\Anaconda3\\envs\\tf1\\lib\\site-packages\\IPython\\core\\ultratb.py\", line 1268, in structured_traceback\n",
      "    self, etype, value, tb, tb_offset, number_of_lines_of_context\n",
      "  File \"C:\\ProgramData\\Anaconda3\\envs\\tf1\\lib\\site-packages\\IPython\\core\\ultratb.py\", line 1125, in structured_traceback\n",
      "    tb_offset)\n",
      "  File \"C:\\ProgramData\\Anaconda3\\envs\\tf1\\lib\\site-packages\\IPython\\core\\ultratb.py\", line 1082, in format_exception_as_a_whole\n",
      "    last_unique, recursion_repeat = find_recursion(orig_etype, evalue, records)\n",
      "  File \"C:\\ProgramData\\Anaconda3\\envs\\tf1\\lib\\site-packages\\IPython\\core\\ultratb.py\", line 382, in find_recursion\n",
      "    return len(records), 0\n",
      "TypeError: object of type 'NoneType' has no len()\n",
      "\n",
      "During handling of the above exception, another exception occurred:\n",
      "\n",
      "Traceback (most recent call last):\n",
      "  File \"C:\\ProgramData\\Anaconda3\\envs\\tf1\\lib\\site-packages\\IPython\\core\\interactiveshell.py\", line 2061, in showtraceback\n",
      "    stb = value._render_traceback_()\n",
      "AttributeError: 'TypeError' object has no attribute '_render_traceback_'\n",
      "\n",
      "During handling of the above exception, another exception occurred:\n",
      "\n",
      "Traceback (most recent call last):\n",
      "  File \"C:\\ProgramData\\Anaconda3\\envs\\tf1\\lib\\site-packages\\IPython\\core\\interactiveshell.py\", line 2944, in _run_cell\n",
      "    return runner(coro)\n",
      "  File \"C:\\ProgramData\\Anaconda3\\envs\\tf1\\lib\\site-packages\\IPython\\core\\async_helpers.py\", line 68, in _pseudo_sync_runner\n",
      "    coro.send(None)\n",
      "  File \"C:\\ProgramData\\Anaconda3\\envs\\tf1\\lib\\site-packages\\IPython\\core\\interactiveshell.py\", line 3170, in run_cell_async\n",
      "    interactivity=interactivity, compiler=compiler, result=result)\n",
      "  File \"C:\\ProgramData\\Anaconda3\\envs\\tf1\\lib\\site-packages\\IPython\\core\\interactiveshell.py\", line 3380, in run_ast_nodes\n",
      "    self.showtraceback()\n",
      "  File \"C:\\ProgramData\\Anaconda3\\envs\\tf1\\lib\\site-packages\\IPython\\core\\interactiveshell.py\", line 2064, in showtraceback\n",
      "    value, tb, tb_offset=tb_offset)\n",
      "  File \"C:\\ProgramData\\Anaconda3\\envs\\tf1\\lib\\site-packages\\IPython\\core\\ultratb.py\", line 1368, in structured_traceback\n",
      "    self, etype, value, tb, tb_offset, number_of_lines_of_context)\n",
      "  File \"C:\\ProgramData\\Anaconda3\\envs\\tf1\\lib\\site-packages\\IPython\\core\\ultratb.py\", line 1268, in structured_traceback\n",
      "    self, etype, value, tb, tb_offset, number_of_lines_of_context\n",
      "  File \"C:\\ProgramData\\Anaconda3\\envs\\tf1\\lib\\site-packages\\IPython\\core\\ultratb.py\", line 1143, in structured_traceback\n",
      "    chained_exceptions_tb_offset)\n",
      "  File \"C:\\ProgramData\\Anaconda3\\envs\\tf1\\lib\\site-packages\\IPython\\core\\ultratb.py\", line 1082, in format_exception_as_a_whole\n",
      "    last_unique, recursion_repeat = find_recursion(orig_etype, evalue, records)\n",
      "  File \"C:\\ProgramData\\Anaconda3\\envs\\tf1\\lib\\site-packages\\IPython\\core\\ultratb.py\", line 382, in find_recursion\n",
      "    return len(records), 0\n",
      "TypeError: object of type 'NoneType' has no len()\n",
      "\n",
      "During handling of the above exception, another exception occurred:\n",
      "\n",
      "Traceback (most recent call last):\n",
      "  File \"C:\\ProgramData\\Anaconda3\\envs\\tf1\\lib\\site-packages\\IPython\\core\\interactiveshell.py\", line 2061, in showtraceback\n",
      "    stb = value._render_traceback_()\n",
      "AttributeError: 'TypeError' object has no attribute '_render_traceback_'\n",
      "\n",
      "During handling of the above exception, another exception occurred:\n",
      "\n",
      "Traceback (most recent call last):\n",
      "  File \"C:\\ProgramData\\Anaconda3\\envs\\tf1\\lib\\site-packages\\IPython\\core\\ultratb.py\", line 1101, in get_records\n",
      "    return _fixed_getinnerframes(etb, number_of_lines_of_context, tb_offset)\n",
      "  File \"C:\\ProgramData\\Anaconda3\\envs\\tf1\\lib\\site-packages\\IPython\\core\\ultratb.py\", line 248, in wrapped\n",
      "    return f(*args, **kwargs)\n",
      "  File \"C:\\ProgramData\\Anaconda3\\envs\\tf1\\lib\\site-packages\\IPython\\core\\ultratb.py\", line 281, in _fixed_getinnerframes\n",
      "    records = fix_frame_records_filenames(inspect.getinnerframes(etb, context))\n",
      "  File \"C:\\ProgramData\\Anaconda3\\envs\\tf1\\lib\\inspect.py\", line 1502, in getinnerframes\n",
      "    frameinfo = (tb.tb_frame,) + getframeinfo(tb, context)\n",
      "  File \"C:\\ProgramData\\Anaconda3\\envs\\tf1\\lib\\inspect.py\", line 1460, in getframeinfo\n",
      "    filename = getsourcefile(frame) or getfile(frame)\n",
      "  File \"C:\\ProgramData\\Anaconda3\\envs\\tf1\\lib\\inspect.py\", line 696, in getsourcefile\n",
      "    if getattr(getmodule(object, filename), '__loader__', None) is not None:\n",
      "  File \"C:\\ProgramData\\Anaconda3\\envs\\tf1\\lib\\inspect.py\", line 733, in getmodule\n",
      "    if ismodule(module) and hasattr(module, '__file__'):\n",
      "  File \"C:\\ProgramData\\Anaconda3\\envs\\tf1\\lib\\site-packages\\tensorflow\\__init__.py\", line 50, in __getattr__\n",
      "    module = self._load()\n",
      "  File \"C:\\ProgramData\\Anaconda3\\envs\\tf1\\lib\\site-packages\\tensorflow\\__init__.py\", line 44, in _load\n",
      "    module = _importlib.import_module(self.__name__)\n",
      "  File \"C:\\ProgramData\\Anaconda3\\envs\\tf1\\lib\\importlib\\__init__.py\", line 127, in import_module\n",
      "    return _bootstrap._gcd_import(name[level:], package, level)\n",
      "  File \"<frozen importlib._bootstrap>\", line 1006, in _gcd_import\n",
      "  File \"<frozen importlib._bootstrap>\", line 983, in _find_and_load\n",
      "  File \"<frozen importlib._bootstrap>\", line 965, in _find_and_load_unlocked\n",
      "ModuleNotFoundError: No module named 'tensorflow_core.estimator'\n"
     ]
    }
   ],
   "metadata": {}
  },
  {
   "cell_type": "code",
   "execution_count": 2,
   "source": [
    "converter = tf.lite.TFLiteConverter.from_frozen_graph(\r\n",
    "        \"Models/resnet18/saved_model.pb\", ['input'], ['output'])\r\n",
    "tflite_model = converter.convert()\r\n",
    "open(\"Models/resnet18.tflite\", \"wb\").write(tflite_model)"
   ],
   "outputs": [
    {
     "output_type": "stream",
     "name": "stderr",
     "text": [
      "ERROR:root:Internal Python error in the inspect module.\n",
      "Below is the traceback from this internal error.\n",
      "\n",
      "ERROR:root:Internal Python error in the inspect module.\n",
      "Below is the traceback from this internal error.\n",
      "\n",
      "ERROR:root:Internal Python error in the inspect module.\n",
      "Below is the traceback from this internal error.\n",
      "\n"
     ]
    },
    {
     "output_type": "stream",
     "name": "stdout",
     "text": [
      "Ignore 'tcmalloc: large alloc' warnings.\n",
      "Traceback (most recent call last):\n",
      "  File \"C:\\ProgramData\\Anaconda3\\envs\\tf1\\lib\\site-packages\\tensorflow_core\\lite\\python\\lite.py\", line 674, in from_frozen_graph\n",
      "    graph_def.ParseFromString(file_content)\n",
      "  File \"C:\\ProgramData\\Anaconda3\\envs\\tf1\\lib\\site-packages\\google\\protobuf\\message.py\", line 199, in ParseFromString\n",
      "    return self.MergeFromString(serialized)\n",
      "  File \"C:\\ProgramData\\Anaconda3\\envs\\tf1\\lib\\site-packages\\google\\protobuf\\internal\\python_message.py\", line 1139, in MergeFromString\n",
      "    if self._InternalParse(serialized, 0, length) != length:\n",
      "  File \"C:\\ProgramData\\Anaconda3\\envs\\tf1\\lib\\site-packages\\google\\protobuf\\internal\\python_message.py\", line 1206, in InternalParse\n",
      "    pos = field_decoder(buffer, new_pos, end, self, field_dict)\n",
      "  File \"C:\\ProgramData\\Anaconda3\\envs\\tf1\\lib\\site-packages\\google\\protobuf\\internal\\decoder.py\", line 754, in DecodeField\n",
      "    if value._InternalParse(buffer, pos, new_pos) != new_pos:\n",
      "  File \"C:\\ProgramData\\Anaconda3\\envs\\tf1\\lib\\site-packages\\google\\protobuf\\internal\\python_message.py\", line 1206, in InternalParse\n",
      "    pos = field_decoder(buffer, new_pos, end, self, field_dict)\n",
      "  File \"C:\\ProgramData\\Anaconda3\\envs\\tf1\\lib\\site-packages\\google\\protobuf\\internal\\decoder.py\", line 733, in DecodeRepeatedField\n",
      "    if value.add()._InternalParse(buffer, pos, new_pos) != new_pos:\n",
      "  File \"C:\\ProgramData\\Anaconda3\\envs\\tf1\\lib\\site-packages\\google\\protobuf\\internal\\python_message.py\", line 1206, in InternalParse\n",
      "    pos = field_decoder(buffer, new_pos, end, self, field_dict)\n",
      "  File \"C:\\ProgramData\\Anaconda3\\envs\\tf1\\lib\\site-packages\\google\\protobuf\\internal\\decoder.py\", line 888, in DecodeMap\n",
      "    if submsg._InternalParse(buffer, pos, new_pos) != new_pos:\n",
      "  File \"C:\\ProgramData\\Anaconda3\\envs\\tf1\\lib\\site-packages\\google\\protobuf\\internal\\python_message.py\", line 1193, in InternalParse\n",
      "    buffer, new_pos, wire_type)  # pylint: disable=protected-access\n",
      "  File \"C:\\ProgramData\\Anaconda3\\envs\\tf1\\lib\\site-packages\\google\\protobuf\\internal\\decoder.py\", line 989, in _DecodeUnknownField\n",
      "    (data, pos) = _DecodeUnknownFieldSet(buffer, pos)\n",
      "  File \"C:\\ProgramData\\Anaconda3\\envs\\tf1\\lib\\site-packages\\google\\protobuf\\internal\\decoder.py\", line 968, in _DecodeUnknownFieldSet\n",
      "    (data, pos) = _DecodeUnknownField(buffer, pos, wire_type)\n",
      "  File \"C:\\ProgramData\\Anaconda3\\envs\\tf1\\lib\\site-packages\\google\\protobuf\\internal\\decoder.py\", line 993, in _DecodeUnknownField\n",
      "    raise _DecodeError('Wrong wire type in tag.')\n",
      "google.protobuf.message.DecodeError: Wrong wire type in tag.\n",
      "\n",
      "During handling of the above exception, another exception occurred:\n",
      "\n",
      "Traceback (most recent call last):\n",
      "  File \"C:\\ProgramData\\Anaconda3\\envs\\tf1\\lib\\site-packages\\IPython\\core\\interactiveshell.py\", line 3441, in run_code\n",
      "    exec(code_obj, self.user_global_ns, self.user_ns)\n",
      "  File \"C:\\Users\\zarre\\AppData\\Local\\Temp/ipykernel_32720/858210436.py\", line 2, in <module>\n",
      "    \"Models/resnet18/saved_model.pb\", ['input'], ['output'])\n",
      "  File \"C:\\ProgramData\\Anaconda3\\envs\\tf1\\lib\\site-packages\\tensorflow_core\\lite\\python\\lite.py\", line 681, in from_frozen_graph\n",
      "    file_content = file_content.decode(\"utf-8\")\n",
      "UnicodeDecodeError: 'utf-8' codec can't decode byte 0xaf in position 5: invalid start byte\n",
      "\n",
      "During handling of the above exception, another exception occurred:\n",
      "\n",
      "Traceback (most recent call last):\n",
      "  File \"C:\\ProgramData\\Anaconda3\\envs\\tf1\\lib\\site-packages\\IPython\\core\\interactiveshell.py\", line 2061, in showtraceback\n",
      "    stb = value._render_traceback_()\n",
      "AttributeError: 'UnicodeDecodeError' object has no attribute '_render_traceback_'\n",
      "\n",
      "During handling of the above exception, another exception occurred:\n",
      "\n",
      "Traceback (most recent call last):\n",
      "  File \"C:\\ProgramData\\Anaconda3\\envs\\tf1\\lib\\site-packages\\IPython\\core\\ultratb.py\", line 1101, in get_records\n",
      "    return _fixed_getinnerframes(etb, number_of_lines_of_context, tb_offset)\n",
      "  File \"C:\\ProgramData\\Anaconda3\\envs\\tf1\\lib\\site-packages\\IPython\\core\\ultratb.py\", line 248, in wrapped\n",
      "    return f(*args, **kwargs)\n",
      "  File \"C:\\ProgramData\\Anaconda3\\envs\\tf1\\lib\\site-packages\\IPython\\core\\ultratb.py\", line 281, in _fixed_getinnerframes\n",
      "    records = fix_frame_records_filenames(inspect.getinnerframes(etb, context))\n",
      "  File \"C:\\ProgramData\\Anaconda3\\envs\\tf1\\lib\\inspect.py\", line 1502, in getinnerframes\n",
      "    frameinfo = (tb.tb_frame,) + getframeinfo(tb, context)\n",
      "  File \"C:\\ProgramData\\Anaconda3\\envs\\tf1\\lib\\inspect.py\", line 1460, in getframeinfo\n",
      "    filename = getsourcefile(frame) or getfile(frame)\n",
      "  File \"C:\\ProgramData\\Anaconda3\\envs\\tf1\\lib\\inspect.py\", line 696, in getsourcefile\n",
      "    if getattr(getmodule(object, filename), '__loader__', None) is not None:\n",
      "  File \"C:\\ProgramData\\Anaconda3\\envs\\tf1\\lib\\inspect.py\", line 733, in getmodule\n",
      "    if ismodule(module) and hasattr(module, '__file__'):\n",
      "  File \"C:\\ProgramData\\Anaconda3\\envs\\tf1\\lib\\site-packages\\tensorflow\\__init__.py\", line 50, in __getattr__\n",
      "    module = self._load()\n",
      "  File \"C:\\ProgramData\\Anaconda3\\envs\\tf1\\lib\\site-packages\\tensorflow\\__init__.py\", line 44, in _load\n",
      "    module = _importlib.import_module(self.__name__)\n",
      "  File \"C:\\ProgramData\\Anaconda3\\envs\\tf1\\lib\\importlib\\__init__.py\", line 127, in import_module\n",
      "    return _bootstrap._gcd_import(name[level:], package, level)\n",
      "  File \"<frozen importlib._bootstrap>\", line 1006, in _gcd_import\n",
      "  File \"<frozen importlib._bootstrap>\", line 983, in _find_and_load\n",
      "  File \"<frozen importlib._bootstrap>\", line 967, in _find_and_load_unlocked\n",
      "  File \"<frozen importlib._bootstrap>\", line 677, in _load_unlocked\n",
      "  File \"<frozen importlib._bootstrap_external>\", line 728, in exec_module\n",
      "  File \"<frozen importlib._bootstrap>\", line 219, in _call_with_frames_removed\n",
      "  File \"C:\\ProgramData\\Anaconda3\\envs\\tf1\\lib\\site-packages\\tensorflow_core\\contrib\\__init__.py\", line 39, in <module>\n",
      "    from tensorflow.contrib import compiler\n",
      "  File \"C:\\ProgramData\\Anaconda3\\envs\\tf1\\lib\\site-packages\\tensorflow_core\\contrib\\compiler\\__init__.py\", line 21, in <module>\n",
      "    from tensorflow.contrib.compiler import jit\n",
      "  File \"C:\\ProgramData\\Anaconda3\\envs\\tf1\\lib\\site-packages\\tensorflow_core\\contrib\\compiler\\__init__.py\", line 22, in <module>\n",
      "    from tensorflow.contrib.compiler import xla\n",
      "  File \"C:\\ProgramData\\Anaconda3\\envs\\tf1\\lib\\site-packages\\tensorflow_core\\contrib\\compiler\\xla.py\", line 22, in <module>\n",
      "    from tensorflow.python.estimator import model_fn as model_fn_lib\n",
      "  File \"C:\\ProgramData\\Anaconda3\\envs\\tf1\\lib\\site-packages\\tensorflow_core\\python\\estimator\\model_fn.py\", line 26, in <module>\n",
      "    from tensorflow_estimator.python.estimator import model_fn\n",
      "  File \"C:\\ProgramData\\Anaconda3\\envs\\tf1\\lib\\site-packages\\tensorflow_estimator\\python\\estimator\\model_fn.py\", line 29, in <module>\n",
      "    from tensorflow.python.types import core\n",
      "ModuleNotFoundError: No module named 'tensorflow.python.types'\n",
      "Traceback (most recent call last):\n",
      "  File \"C:\\ProgramData\\Anaconda3\\envs\\tf1\\lib\\site-packages\\tensorflow_core\\lite\\python\\lite.py\", line 674, in from_frozen_graph\n",
      "    graph_def.ParseFromString(file_content)\n",
      "  File \"C:\\ProgramData\\Anaconda3\\envs\\tf1\\lib\\site-packages\\google\\protobuf\\message.py\", line 199, in ParseFromString\n",
      "    return self.MergeFromString(serialized)\n",
      "  File \"C:\\ProgramData\\Anaconda3\\envs\\tf1\\lib\\site-packages\\google\\protobuf\\internal\\python_message.py\", line 1139, in MergeFromString\n",
      "    if self._InternalParse(serialized, 0, length) != length:\n",
      "  File \"C:\\ProgramData\\Anaconda3\\envs\\tf1\\lib\\site-packages\\google\\protobuf\\internal\\python_message.py\", line 1206, in InternalParse\n",
      "    pos = field_decoder(buffer, new_pos, end, self, field_dict)\n",
      "  File \"C:\\ProgramData\\Anaconda3\\envs\\tf1\\lib\\site-packages\\google\\protobuf\\internal\\decoder.py\", line 754, in DecodeField\n",
      "    if value._InternalParse(buffer, pos, new_pos) != new_pos:\n",
      "  File \"C:\\ProgramData\\Anaconda3\\envs\\tf1\\lib\\site-packages\\google\\protobuf\\internal\\python_message.py\", line 1206, in InternalParse\n",
      "    pos = field_decoder(buffer, new_pos, end, self, field_dict)\n",
      "  File \"C:\\ProgramData\\Anaconda3\\envs\\tf1\\lib\\site-packages\\google\\protobuf\\internal\\decoder.py\", line 733, in DecodeRepeatedField\n",
      "    if value.add()._InternalParse(buffer, pos, new_pos) != new_pos:\n",
      "  File \"C:\\ProgramData\\Anaconda3\\envs\\tf1\\lib\\site-packages\\google\\protobuf\\internal\\python_message.py\", line 1206, in InternalParse\n",
      "    pos = field_decoder(buffer, new_pos, end, self, field_dict)\n",
      "  File \"C:\\ProgramData\\Anaconda3\\envs\\tf1\\lib\\site-packages\\google\\protobuf\\internal\\decoder.py\", line 888, in DecodeMap\n",
      "    if submsg._InternalParse(buffer, pos, new_pos) != new_pos:\n",
      "  File \"C:\\ProgramData\\Anaconda3\\envs\\tf1\\lib\\site-packages\\google\\protobuf\\internal\\python_message.py\", line 1193, in InternalParse\n",
      "    buffer, new_pos, wire_type)  # pylint: disable=protected-access\n",
      "  File \"C:\\ProgramData\\Anaconda3\\envs\\tf1\\lib\\site-packages\\google\\protobuf\\internal\\decoder.py\", line 989, in _DecodeUnknownField\n",
      "    (data, pos) = _DecodeUnknownFieldSet(buffer, pos)\n",
      "  File \"C:\\ProgramData\\Anaconda3\\envs\\tf1\\lib\\site-packages\\google\\protobuf\\internal\\decoder.py\", line 968, in _DecodeUnknownFieldSet\n",
      "    (data, pos) = _DecodeUnknownField(buffer, pos, wire_type)\n",
      "  File \"C:\\ProgramData\\Anaconda3\\envs\\tf1\\lib\\site-packages\\google\\protobuf\\internal\\decoder.py\", line 993, in _DecodeUnknownField\n",
      "    raise _DecodeError('Wrong wire type in tag.')\n",
      "google.protobuf.message.DecodeError: Wrong wire type in tag.\n",
      "\n",
      "During handling of the above exception, another exception occurred:\n",
      "\n",
      "Traceback (most recent call last):\n",
      "  File \"C:\\ProgramData\\Anaconda3\\envs\\tf1\\lib\\site-packages\\IPython\\core\\interactiveshell.py\", line 3441, in run_code\n",
      "    exec(code_obj, self.user_global_ns, self.user_ns)\n",
      "  File \"C:\\Users\\zarre\\AppData\\Local\\Temp/ipykernel_32720/858210436.py\", line 2, in <module>\n",
      "    \"Models/resnet18/saved_model.pb\", ['input'], ['output'])\n",
      "  File \"C:\\ProgramData\\Anaconda3\\envs\\tf1\\lib\\site-packages\\tensorflow_core\\lite\\python\\lite.py\", line 681, in from_frozen_graph\n",
      "    file_content = file_content.decode(\"utf-8\")\n",
      "UnicodeDecodeError: 'utf-8' codec can't decode byte 0xaf in position 5: invalid start byte\n",
      "\n",
      "During handling of the above exception, another exception occurred:\n",
      "\n",
      "Traceback (most recent call last):\n",
      "  File \"C:\\ProgramData\\Anaconda3\\envs\\tf1\\lib\\site-packages\\IPython\\core\\interactiveshell.py\", line 2061, in showtraceback\n",
      "    stb = value._render_traceback_()\n",
      "AttributeError: 'UnicodeDecodeError' object has no attribute '_render_traceback_'\n",
      "\n",
      "During handling of the above exception, another exception occurred:\n",
      "\n",
      "Traceback (most recent call last):\n",
      "  File \"C:\\ProgramData\\Anaconda3\\envs\\tf1\\lib\\site-packages\\IPython\\core\\interactiveshell.py\", line 3361, in run_ast_nodes\n",
      "    if (await self.run_code(code, result,  async_=asy)):\n",
      "  File \"C:\\ProgramData\\Anaconda3\\envs\\tf1\\lib\\site-packages\\IPython\\core\\interactiveshell.py\", line 3458, in run_code\n",
      "    self.showtraceback(running_compiled_code=True)\n",
      "  File \"C:\\ProgramData\\Anaconda3\\envs\\tf1\\lib\\site-packages\\IPython\\core\\interactiveshell.py\", line 2064, in showtraceback\n",
      "    value, tb, tb_offset=tb_offset)\n",
      "  File \"C:\\ProgramData\\Anaconda3\\envs\\tf1\\lib\\site-packages\\IPython\\core\\ultratb.py\", line 1368, in structured_traceback\n",
      "    self, etype, value, tb, tb_offset, number_of_lines_of_context)\n",
      "  File \"C:\\ProgramData\\Anaconda3\\envs\\tf1\\lib\\site-packages\\IPython\\core\\ultratb.py\", line 1268, in structured_traceback\n",
      "    self, etype, value, tb, tb_offset, number_of_lines_of_context\n",
      "  File \"C:\\ProgramData\\Anaconda3\\envs\\tf1\\lib\\site-packages\\IPython\\core\\ultratb.py\", line 1125, in structured_traceback\n",
      "    tb_offset)\n",
      "  File \"C:\\ProgramData\\Anaconda3\\envs\\tf1\\lib\\site-packages\\IPython\\core\\ultratb.py\", line 1082, in format_exception_as_a_whole\n",
      "    last_unique, recursion_repeat = find_recursion(orig_etype, evalue, records)\n",
      "  File \"C:\\ProgramData\\Anaconda3\\envs\\tf1\\lib\\site-packages\\IPython\\core\\ultratb.py\", line 382, in find_recursion\n",
      "    return len(records), 0\n",
      "TypeError: object of type 'NoneType' has no len()\n",
      "\n",
      "During handling of the above exception, another exception occurred:\n",
      "\n",
      "Traceback (most recent call last):\n",
      "  File \"C:\\ProgramData\\Anaconda3\\envs\\tf1\\lib\\site-packages\\IPython\\core\\interactiveshell.py\", line 2061, in showtraceback\n",
      "    stb = value._render_traceback_()\n",
      "AttributeError: 'TypeError' object has no attribute '_render_traceback_'\n",
      "\n",
      "During handling of the above exception, another exception occurred:\n",
      "\n",
      "Traceback (most recent call last):\n",
      "  File \"C:\\ProgramData\\Anaconda3\\envs\\tf1\\lib\\site-packages\\IPython\\core\\ultratb.py\", line 1101, in get_records\n",
      "    return _fixed_getinnerframes(etb, number_of_lines_of_context, tb_offset)\n",
      "  File \"C:\\ProgramData\\Anaconda3\\envs\\tf1\\lib\\site-packages\\IPython\\core\\ultratb.py\", line 248, in wrapped\n",
      "    return f(*args, **kwargs)\n",
      "  File \"C:\\ProgramData\\Anaconda3\\envs\\tf1\\lib\\site-packages\\IPython\\core\\ultratb.py\", line 281, in _fixed_getinnerframes\n",
      "    records = fix_frame_records_filenames(inspect.getinnerframes(etb, context))\n",
      "  File \"C:\\ProgramData\\Anaconda3\\envs\\tf1\\lib\\inspect.py\", line 1502, in getinnerframes\n",
      "    frameinfo = (tb.tb_frame,) + getframeinfo(tb, context)\n",
      "  File \"C:\\ProgramData\\Anaconda3\\envs\\tf1\\lib\\inspect.py\", line 1460, in getframeinfo\n",
      "    filename = getsourcefile(frame) or getfile(frame)\n",
      "  File \"C:\\ProgramData\\Anaconda3\\envs\\tf1\\lib\\inspect.py\", line 696, in getsourcefile\n",
      "    if getattr(getmodule(object, filename), '__loader__', None) is not None:\n",
      "  File \"C:\\ProgramData\\Anaconda3\\envs\\tf1\\lib\\inspect.py\", line 733, in getmodule\n",
      "    if ismodule(module) and hasattr(module, '__file__'):\n",
      "  File \"C:\\ProgramData\\Anaconda3\\envs\\tf1\\lib\\site-packages\\tensorflow\\__init__.py\", line 50, in __getattr__\n",
      "    module = self._load()\n",
      "  File \"C:\\ProgramData\\Anaconda3\\envs\\tf1\\lib\\site-packages\\tensorflow\\__init__.py\", line 44, in _load\n",
      "    module = _importlib.import_module(self.__name__)\n",
      "  File \"C:\\ProgramData\\Anaconda3\\envs\\tf1\\lib\\importlib\\__init__.py\", line 127, in import_module\n",
      "    return _bootstrap._gcd_import(name[level:], package, level)\n",
      "  File \"<frozen importlib._bootstrap>\", line 1006, in _gcd_import\n",
      "  File \"<frozen importlib._bootstrap>\", line 983, in _find_and_load\n",
      "  File \"<frozen importlib._bootstrap>\", line 965, in _find_and_load_unlocked\n",
      "ModuleNotFoundError: No module named 'tensorflow_core.estimator'\n",
      "Traceback (most recent call last):\n",
      "  File \"C:\\ProgramData\\Anaconda3\\envs\\tf1\\lib\\site-packages\\tensorflow_core\\lite\\python\\lite.py\", line 674, in from_frozen_graph\n",
      "    graph_def.ParseFromString(file_content)\n",
      "  File \"C:\\ProgramData\\Anaconda3\\envs\\tf1\\lib\\site-packages\\google\\protobuf\\message.py\", line 199, in ParseFromString\n",
      "    return self.MergeFromString(serialized)\n",
      "  File \"C:\\ProgramData\\Anaconda3\\envs\\tf1\\lib\\site-packages\\google\\protobuf\\internal\\python_message.py\", line 1139, in MergeFromString\n",
      "    if self._InternalParse(serialized, 0, length) != length:\n",
      "  File \"C:\\ProgramData\\Anaconda3\\envs\\tf1\\lib\\site-packages\\google\\protobuf\\internal\\python_message.py\", line 1206, in InternalParse\n",
      "    pos = field_decoder(buffer, new_pos, end, self, field_dict)\n",
      "  File \"C:\\ProgramData\\Anaconda3\\envs\\tf1\\lib\\site-packages\\google\\protobuf\\internal\\decoder.py\", line 754, in DecodeField\n",
      "    if value._InternalParse(buffer, pos, new_pos) != new_pos:\n",
      "  File \"C:\\ProgramData\\Anaconda3\\envs\\tf1\\lib\\site-packages\\google\\protobuf\\internal\\python_message.py\", line 1206, in InternalParse\n",
      "    pos = field_decoder(buffer, new_pos, end, self, field_dict)\n",
      "  File \"C:\\ProgramData\\Anaconda3\\envs\\tf1\\lib\\site-packages\\google\\protobuf\\internal\\decoder.py\", line 733, in DecodeRepeatedField\n",
      "    if value.add()._InternalParse(buffer, pos, new_pos) != new_pos:\n",
      "  File \"C:\\ProgramData\\Anaconda3\\envs\\tf1\\lib\\site-packages\\google\\protobuf\\internal\\python_message.py\", line 1206, in InternalParse\n",
      "    pos = field_decoder(buffer, new_pos, end, self, field_dict)\n",
      "  File \"C:\\ProgramData\\Anaconda3\\envs\\tf1\\lib\\site-packages\\google\\protobuf\\internal\\decoder.py\", line 888, in DecodeMap\n",
      "    if submsg._InternalParse(buffer, pos, new_pos) != new_pos:\n",
      "  File \"C:\\ProgramData\\Anaconda3\\envs\\tf1\\lib\\site-packages\\google\\protobuf\\internal\\python_message.py\", line 1193, in InternalParse\n",
      "    buffer, new_pos, wire_type)  # pylint: disable=protected-access\n",
      "  File \"C:\\ProgramData\\Anaconda3\\envs\\tf1\\lib\\site-packages\\google\\protobuf\\internal\\decoder.py\", line 989, in _DecodeUnknownField\n",
      "    (data, pos) = _DecodeUnknownFieldSet(buffer, pos)\n",
      "  File \"C:\\ProgramData\\Anaconda3\\envs\\tf1\\lib\\site-packages\\google\\protobuf\\internal\\decoder.py\", line 968, in _DecodeUnknownFieldSet\n",
      "    (data, pos) = _DecodeUnknownField(buffer, pos, wire_type)\n",
      "  File \"C:\\ProgramData\\Anaconda3\\envs\\tf1\\lib\\site-packages\\google\\protobuf\\internal\\decoder.py\", line 993, in _DecodeUnknownField\n",
      "    raise _DecodeError('Wrong wire type in tag.')\n",
      "google.protobuf.message.DecodeError: Wrong wire type in tag.\n",
      "\n",
      "During handling of the above exception, another exception occurred:\n",
      "\n",
      "Traceback (most recent call last):\n",
      "  File \"C:\\ProgramData\\Anaconda3\\envs\\tf1\\lib\\site-packages\\IPython\\core\\interactiveshell.py\", line 3441, in run_code\n",
      "    exec(code_obj, self.user_global_ns, self.user_ns)\n",
      "  File \"C:\\Users\\zarre\\AppData\\Local\\Temp/ipykernel_32720/858210436.py\", line 2, in <module>\n",
      "    \"Models/resnet18/saved_model.pb\", ['input'], ['output'])\n",
      "  File \"C:\\ProgramData\\Anaconda3\\envs\\tf1\\lib\\site-packages\\tensorflow_core\\lite\\python\\lite.py\", line 681, in from_frozen_graph\n",
      "    file_content = file_content.decode(\"utf-8\")\n",
      "UnicodeDecodeError: 'utf-8' codec can't decode byte 0xaf in position 5: invalid start byte\n",
      "\n",
      "During handling of the above exception, another exception occurred:\n",
      "\n",
      "Traceback (most recent call last):\n",
      "  File \"C:\\ProgramData\\Anaconda3\\envs\\tf1\\lib\\site-packages\\IPython\\core\\interactiveshell.py\", line 2061, in showtraceback\n",
      "    stb = value._render_traceback_()\n",
      "AttributeError: 'UnicodeDecodeError' object has no attribute '_render_traceback_'\n",
      "\n",
      "During handling of the above exception, another exception occurred:\n",
      "\n",
      "Traceback (most recent call last):\n",
      "  File \"C:\\ProgramData\\Anaconda3\\envs\\tf1\\lib\\site-packages\\IPython\\core\\interactiveshell.py\", line 3361, in run_ast_nodes\n",
      "    if (await self.run_code(code, result,  async_=asy)):\n",
      "  File \"C:\\ProgramData\\Anaconda3\\envs\\tf1\\lib\\site-packages\\IPython\\core\\interactiveshell.py\", line 3458, in run_code\n",
      "    self.showtraceback(running_compiled_code=True)\n",
      "  File \"C:\\ProgramData\\Anaconda3\\envs\\tf1\\lib\\site-packages\\IPython\\core\\interactiveshell.py\", line 2064, in showtraceback\n",
      "    value, tb, tb_offset=tb_offset)\n",
      "  File \"C:\\ProgramData\\Anaconda3\\envs\\tf1\\lib\\site-packages\\IPython\\core\\ultratb.py\", line 1368, in structured_traceback\n",
      "    self, etype, value, tb, tb_offset, number_of_lines_of_context)\n",
      "  File \"C:\\ProgramData\\Anaconda3\\envs\\tf1\\lib\\site-packages\\IPython\\core\\ultratb.py\", line 1268, in structured_traceback\n",
      "    self, etype, value, tb, tb_offset, number_of_lines_of_context\n",
      "  File \"C:\\ProgramData\\Anaconda3\\envs\\tf1\\lib\\site-packages\\IPython\\core\\ultratb.py\", line 1125, in structured_traceback\n",
      "    tb_offset)\n",
      "  File \"C:\\ProgramData\\Anaconda3\\envs\\tf1\\lib\\site-packages\\IPython\\core\\ultratb.py\", line 1082, in format_exception_as_a_whole\n",
      "    last_unique, recursion_repeat = find_recursion(orig_etype, evalue, records)\n",
      "  File \"C:\\ProgramData\\Anaconda3\\envs\\tf1\\lib\\site-packages\\IPython\\core\\ultratb.py\", line 382, in find_recursion\n",
      "    return len(records), 0\n",
      "TypeError: object of type 'NoneType' has no len()\n",
      "\n",
      "During handling of the above exception, another exception occurred:\n",
      "\n",
      "Traceback (most recent call last):\n",
      "  File \"C:\\ProgramData\\Anaconda3\\envs\\tf1\\lib\\site-packages\\IPython\\core\\interactiveshell.py\", line 2061, in showtraceback\n",
      "    stb = value._render_traceback_()\n",
      "AttributeError: 'TypeError' object has no attribute '_render_traceback_'\n",
      "\n",
      "During handling of the above exception, another exception occurred:\n",
      "\n",
      "Traceback (most recent call last):\n",
      "  File \"C:\\ProgramData\\Anaconda3\\envs\\tf1\\lib\\site-packages\\IPython\\core\\interactiveshell.py\", line 2944, in _run_cell\n",
      "    return runner(coro)\n",
      "  File \"C:\\ProgramData\\Anaconda3\\envs\\tf1\\lib\\site-packages\\IPython\\core\\async_helpers.py\", line 68, in _pseudo_sync_runner\n",
      "    coro.send(None)\n",
      "  File \"C:\\ProgramData\\Anaconda3\\envs\\tf1\\lib\\site-packages\\IPython\\core\\interactiveshell.py\", line 3170, in run_cell_async\n",
      "    interactivity=interactivity, compiler=compiler, result=result)\n",
      "  File \"C:\\ProgramData\\Anaconda3\\envs\\tf1\\lib\\site-packages\\IPython\\core\\interactiveshell.py\", line 3380, in run_ast_nodes\n",
      "    self.showtraceback()\n",
      "  File \"C:\\ProgramData\\Anaconda3\\envs\\tf1\\lib\\site-packages\\IPython\\core\\interactiveshell.py\", line 2064, in showtraceback\n",
      "    value, tb, tb_offset=tb_offset)\n",
      "  File \"C:\\ProgramData\\Anaconda3\\envs\\tf1\\lib\\site-packages\\IPython\\core\\ultratb.py\", line 1368, in structured_traceback\n",
      "    self, etype, value, tb, tb_offset, number_of_lines_of_context)\n",
      "  File \"C:\\ProgramData\\Anaconda3\\envs\\tf1\\lib\\site-packages\\IPython\\core\\ultratb.py\", line 1268, in structured_traceback\n",
      "    self, etype, value, tb, tb_offset, number_of_lines_of_context\n",
      "  File \"C:\\ProgramData\\Anaconda3\\envs\\tf1\\lib\\site-packages\\IPython\\core\\ultratb.py\", line 1143, in structured_traceback\n",
      "    chained_exceptions_tb_offset)\n",
      "  File \"C:\\ProgramData\\Anaconda3\\envs\\tf1\\lib\\site-packages\\IPython\\core\\ultratb.py\", line 1082, in format_exception_as_a_whole\n",
      "    last_unique, recursion_repeat = find_recursion(orig_etype, evalue, records)\n",
      "  File \"C:\\ProgramData\\Anaconda3\\envs\\tf1\\lib\\site-packages\\IPython\\core\\ultratb.py\", line 382, in find_recursion\n",
      "    return len(records), 0\n",
      "TypeError: object of type 'NoneType' has no len()\n",
      "\n",
      "During handling of the above exception, another exception occurred:\n",
      "\n",
      "Traceback (most recent call last):\n",
      "  File \"C:\\ProgramData\\Anaconda3\\envs\\tf1\\lib\\site-packages\\IPython\\core\\interactiveshell.py\", line 2061, in showtraceback\n",
      "    stb = value._render_traceback_()\n",
      "AttributeError: 'TypeError' object has no attribute '_render_traceback_'\n",
      "\n",
      "During handling of the above exception, another exception occurred:\n",
      "\n",
      "Traceback (most recent call last):\n",
      "  File \"C:\\ProgramData\\Anaconda3\\envs\\tf1\\lib\\site-packages\\IPython\\core\\ultratb.py\", line 1101, in get_records\n",
      "    return _fixed_getinnerframes(etb, number_of_lines_of_context, tb_offset)\n",
      "  File \"C:\\ProgramData\\Anaconda3\\envs\\tf1\\lib\\site-packages\\IPython\\core\\ultratb.py\", line 248, in wrapped\n",
      "    return f(*args, **kwargs)\n",
      "  File \"C:\\ProgramData\\Anaconda3\\envs\\tf1\\lib\\site-packages\\IPython\\core\\ultratb.py\", line 281, in _fixed_getinnerframes\n",
      "    records = fix_frame_records_filenames(inspect.getinnerframes(etb, context))\n",
      "  File \"C:\\ProgramData\\Anaconda3\\envs\\tf1\\lib\\inspect.py\", line 1502, in getinnerframes\n",
      "    frameinfo = (tb.tb_frame,) + getframeinfo(tb, context)\n",
      "  File \"C:\\ProgramData\\Anaconda3\\envs\\tf1\\lib\\inspect.py\", line 1460, in getframeinfo\n",
      "    filename = getsourcefile(frame) or getfile(frame)\n",
      "  File \"C:\\ProgramData\\Anaconda3\\envs\\tf1\\lib\\inspect.py\", line 696, in getsourcefile\n",
      "    if getattr(getmodule(object, filename), '__loader__', None) is not None:\n",
      "  File \"C:\\ProgramData\\Anaconda3\\envs\\tf1\\lib\\inspect.py\", line 733, in getmodule\n",
      "    if ismodule(module) and hasattr(module, '__file__'):\n",
      "  File \"C:\\ProgramData\\Anaconda3\\envs\\tf1\\lib\\site-packages\\tensorflow\\__init__.py\", line 50, in __getattr__\n",
      "    module = self._load()\n",
      "  File \"C:\\ProgramData\\Anaconda3\\envs\\tf1\\lib\\site-packages\\tensorflow\\__init__.py\", line 44, in _load\n",
      "    module = _importlib.import_module(self.__name__)\n",
      "  File \"C:\\ProgramData\\Anaconda3\\envs\\tf1\\lib\\importlib\\__init__.py\", line 127, in import_module\n",
      "    return _bootstrap._gcd_import(name[level:], package, level)\n",
      "  File \"<frozen importlib._bootstrap>\", line 1006, in _gcd_import\n",
      "  File \"<frozen importlib._bootstrap>\", line 983, in _find_and_load\n",
      "  File \"<frozen importlib._bootstrap>\", line 965, in _find_and_load_unlocked\n",
      "ModuleNotFoundError: No module named 'tensorflow_core.estimator'\n"
     ]
    }
   ],
   "metadata": {}
  },
  {
   "cell_type": "code",
   "execution_count": 3,
   "source": [
    "keras.models.load_model(\"Models/resnet18/saved_model.pb\")"
   ],
   "outputs": [
    {
     "output_type": "stream",
     "name": "stderr",
     "text": [
      "ERROR:root:Internal Python error in the inspect module.\n",
      "Below is the traceback from this internal error.\n",
      "\n",
      "ERROR:root:Internal Python error in the inspect module.\n",
      "Below is the traceback from this internal error.\n",
      "\n",
      "ERROR:root:Internal Python error in the inspect module.\n",
      "Below is the traceback from this internal error.\n",
      "\n"
     ]
    },
    {
     "output_type": "stream",
     "name": "stdout",
     "text": [
      "Traceback (most recent call last):\n",
      "  File \"C:\\ProgramData\\Anaconda3\\envs\\tf1\\lib\\site-packages\\IPython\\core\\interactiveshell.py\", line 3441, in run_code\n",
      "    exec(code_obj, self.user_global_ns, self.user_ns)\n",
      "  File \"C:\\Users\\zarre\\AppData\\Local\\Temp/ipykernel_30824/2015509455.py\", line 1, in <module>\n",
      "    keras.models.load_model(\"Models/resnet18/saved_model.pb\")\n",
      "  File \"C:\\ProgramData\\Anaconda3\\envs\\tf1\\lib\\site-packages\\keras\\engine\\saving.py\", line 492, in load_wrapper\n",
      "    return load_function(*args, **kwargs)\n",
      "  File \"C:\\ProgramData\\Anaconda3\\envs\\tf1\\lib\\site-packages\\keras\\engine\\saving.py\", line 583, in load_model\n",
      "    with H5Dict(filepath, mode='r') as h5dict:\n",
      "  File \"C:\\ProgramData\\Anaconda3\\envs\\tf1\\lib\\site-packages\\keras\\utils\\io_utils.py\", line 191, in __init__\n",
      "    self.data = h5py.File(path, mode=mode)\n",
      "  File \"C:\\ProgramData\\Anaconda3\\envs\\tf1\\lib\\site-packages\\h5py\\_hl\\files.py\", line 445, in __init__\n",
      "    swmr=swmr)\n",
      "  File \"C:\\ProgramData\\Anaconda3\\envs\\tf1\\lib\\site-packages\\h5py\\_hl\\files.py\", line 195, in make_fid\n",
      "    fid = h5f.open(name, flags, fapl=fapl)\n",
      "  File \"h5py\\_objects.pyx\", line 54, in h5py._objects.with_phil.wrapper\n",
      "  File \"h5py\\_objects.pyx\", line 55, in h5py._objects.with_phil.wrapper\n",
      "  File \"h5py\\h5f.pyx\", line 96, in h5py.h5f.open\n",
      "OSError: Unable to open file (file signature not found)\n",
      "\n",
      "During handling of the above exception, another exception occurred:\n",
      "\n",
      "Traceback (most recent call last):\n",
      "  File \"C:\\ProgramData\\Anaconda3\\envs\\tf1\\lib\\site-packages\\IPython\\core\\interactiveshell.py\", line 2061, in showtraceback\n",
      "    stb = value._render_traceback_()\n",
      "AttributeError: 'OSError' object has no attribute '_render_traceback_'\n",
      "\n",
      "During handling of the above exception, another exception occurred:\n",
      "\n",
      "Traceback (most recent call last):\n",
      "  File \"C:\\ProgramData\\Anaconda3\\envs\\tf1\\lib\\site-packages\\IPython\\core\\ultratb.py\", line 1101, in get_records\n",
      "    return _fixed_getinnerframes(etb, number_of_lines_of_context, tb_offset)\n",
      "  File \"C:\\ProgramData\\Anaconda3\\envs\\tf1\\lib\\site-packages\\IPython\\core\\ultratb.py\", line 248, in wrapped\n",
      "    return f(*args, **kwargs)\n",
      "  File \"C:\\ProgramData\\Anaconda3\\envs\\tf1\\lib\\site-packages\\IPython\\core\\ultratb.py\", line 281, in _fixed_getinnerframes\n",
      "    records = fix_frame_records_filenames(inspect.getinnerframes(etb, context))\n",
      "  File \"C:\\ProgramData\\Anaconda3\\envs\\tf1\\lib\\inspect.py\", line 1502, in getinnerframes\n",
      "    frameinfo = (tb.tb_frame,) + getframeinfo(tb, context)\n",
      "  File \"C:\\ProgramData\\Anaconda3\\envs\\tf1\\lib\\inspect.py\", line 1460, in getframeinfo\n",
      "    filename = getsourcefile(frame) or getfile(frame)\n",
      "  File \"C:\\ProgramData\\Anaconda3\\envs\\tf1\\lib\\inspect.py\", line 696, in getsourcefile\n",
      "    if getattr(getmodule(object, filename), '__loader__', None) is not None:\n",
      "  File \"C:\\ProgramData\\Anaconda3\\envs\\tf1\\lib\\inspect.py\", line 733, in getmodule\n",
      "    if ismodule(module) and hasattr(module, '__file__'):\n",
      "  File \"C:\\ProgramData\\Anaconda3\\envs\\tf1\\lib\\site-packages\\tensorflow\\__init__.py\", line 50, in __getattr__\n",
      "    module = self._load()\n",
      "  File \"C:\\ProgramData\\Anaconda3\\envs\\tf1\\lib\\site-packages\\tensorflow\\__init__.py\", line 44, in _load\n",
      "    module = _importlib.import_module(self.__name__)\n",
      "  File \"C:\\ProgramData\\Anaconda3\\envs\\tf1\\lib\\importlib\\__init__.py\", line 127, in import_module\n",
      "    return _bootstrap._gcd_import(name[level:], package, level)\n",
      "  File \"<frozen importlib._bootstrap>\", line 1006, in _gcd_import\n",
      "  File \"<frozen importlib._bootstrap>\", line 983, in _find_and_load\n",
      "  File \"<frozen importlib._bootstrap>\", line 967, in _find_and_load_unlocked\n",
      "  File \"<frozen importlib._bootstrap>\", line 677, in _load_unlocked\n",
      "  File \"<frozen importlib._bootstrap_external>\", line 728, in exec_module\n",
      "  File \"<frozen importlib._bootstrap>\", line 219, in _call_with_frames_removed\n",
      "  File \"C:\\ProgramData\\Anaconda3\\envs\\tf1\\lib\\site-packages\\tensorflow_core\\contrib\\__init__.py\", line 39, in <module>\n",
      "    from tensorflow.contrib import compiler\n",
      "  File \"C:\\ProgramData\\Anaconda3\\envs\\tf1\\lib\\site-packages\\tensorflow_core\\contrib\\compiler\\__init__.py\", line 21, in <module>\n",
      "    from tensorflow.contrib.compiler import jit\n",
      "  File \"C:\\ProgramData\\Anaconda3\\envs\\tf1\\lib\\site-packages\\tensorflow_core\\contrib\\compiler\\__init__.py\", line 22, in <module>\n",
      "    from tensorflow.contrib.compiler import xla\n",
      "  File \"C:\\ProgramData\\Anaconda3\\envs\\tf1\\lib\\site-packages\\tensorflow_core\\contrib\\compiler\\xla.py\", line 22, in <module>\n",
      "    from tensorflow.python.estimator import model_fn as model_fn_lib\n",
      "  File \"C:\\ProgramData\\Anaconda3\\envs\\tf1\\lib\\site-packages\\tensorflow_core\\python\\estimator\\model_fn.py\", line 26, in <module>\n",
      "    from tensorflow_estimator.python.estimator import model_fn\n",
      "  File \"C:\\ProgramData\\Anaconda3\\envs\\tf1\\lib\\site-packages\\tensorflow_estimator\\python\\estimator\\model_fn.py\", line 29, in <module>\n",
      "    from tensorflow.python.types import core\n",
      "ModuleNotFoundError: No module named 'tensorflow.python.types'\n",
      "Traceback (most recent call last):\n",
      "  File \"C:\\ProgramData\\Anaconda3\\envs\\tf1\\lib\\site-packages\\IPython\\core\\interactiveshell.py\", line 3441, in run_code\n",
      "    exec(code_obj, self.user_global_ns, self.user_ns)\n",
      "  File \"C:\\Users\\zarre\\AppData\\Local\\Temp/ipykernel_30824/2015509455.py\", line 1, in <module>\n",
      "    keras.models.load_model(\"Models/resnet18/saved_model.pb\")\n",
      "  File \"C:\\ProgramData\\Anaconda3\\envs\\tf1\\lib\\site-packages\\keras\\engine\\saving.py\", line 492, in load_wrapper\n",
      "    return load_function(*args, **kwargs)\n",
      "  File \"C:\\ProgramData\\Anaconda3\\envs\\tf1\\lib\\site-packages\\keras\\engine\\saving.py\", line 583, in load_model\n",
      "    with H5Dict(filepath, mode='r') as h5dict:\n",
      "  File \"C:\\ProgramData\\Anaconda3\\envs\\tf1\\lib\\site-packages\\keras\\utils\\io_utils.py\", line 191, in __init__\n",
      "    self.data = h5py.File(path, mode=mode)\n",
      "  File \"C:\\ProgramData\\Anaconda3\\envs\\tf1\\lib\\site-packages\\h5py\\_hl\\files.py\", line 445, in __init__\n",
      "    swmr=swmr)\n",
      "  File \"C:\\ProgramData\\Anaconda3\\envs\\tf1\\lib\\site-packages\\h5py\\_hl\\files.py\", line 195, in make_fid\n",
      "    fid = h5f.open(name, flags, fapl=fapl)\n",
      "  File \"h5py\\_objects.pyx\", line 54, in h5py._objects.with_phil.wrapper\n",
      "  File \"h5py\\_objects.pyx\", line 55, in h5py._objects.with_phil.wrapper\n",
      "  File \"h5py\\h5f.pyx\", line 96, in h5py.h5f.open\n",
      "OSError: Unable to open file (file signature not found)\n",
      "\n",
      "During handling of the above exception, another exception occurred:\n",
      "\n",
      "Traceback (most recent call last):\n",
      "  File \"C:\\ProgramData\\Anaconda3\\envs\\tf1\\lib\\site-packages\\IPython\\core\\interactiveshell.py\", line 2061, in showtraceback\n",
      "    stb = value._render_traceback_()\n",
      "AttributeError: 'OSError' object has no attribute '_render_traceback_'\n",
      "\n",
      "During handling of the above exception, another exception occurred:\n",
      "\n",
      "Traceback (most recent call last):\n",
      "  File \"C:\\ProgramData\\Anaconda3\\envs\\tf1\\lib\\site-packages\\IPython\\core\\interactiveshell.py\", line 3361, in run_ast_nodes\n",
      "    if (await self.run_code(code, result,  async_=asy)):\n",
      "  File \"C:\\ProgramData\\Anaconda3\\envs\\tf1\\lib\\site-packages\\IPython\\core\\interactiveshell.py\", line 3458, in run_code\n",
      "    self.showtraceback(running_compiled_code=True)\n",
      "  File \"C:\\ProgramData\\Anaconda3\\envs\\tf1\\lib\\site-packages\\IPython\\core\\interactiveshell.py\", line 2064, in showtraceback\n",
      "    value, tb, tb_offset=tb_offset)\n",
      "  File \"C:\\ProgramData\\Anaconda3\\envs\\tf1\\lib\\site-packages\\IPython\\core\\ultratb.py\", line 1368, in structured_traceback\n",
      "    self, etype, value, tb, tb_offset, number_of_lines_of_context)\n",
      "  File \"C:\\ProgramData\\Anaconda3\\envs\\tf1\\lib\\site-packages\\IPython\\core\\ultratb.py\", line 1268, in structured_traceback\n",
      "    self, etype, value, tb, tb_offset, number_of_lines_of_context\n",
      "  File \"C:\\ProgramData\\Anaconda3\\envs\\tf1\\lib\\site-packages\\IPython\\core\\ultratb.py\", line 1125, in structured_traceback\n",
      "    tb_offset)\n",
      "  File \"C:\\ProgramData\\Anaconda3\\envs\\tf1\\lib\\site-packages\\IPython\\core\\ultratb.py\", line 1082, in format_exception_as_a_whole\n",
      "    last_unique, recursion_repeat = find_recursion(orig_etype, evalue, records)\n",
      "  File \"C:\\ProgramData\\Anaconda3\\envs\\tf1\\lib\\site-packages\\IPython\\core\\ultratb.py\", line 382, in find_recursion\n",
      "    return len(records), 0\n",
      "TypeError: object of type 'NoneType' has no len()\n",
      "\n",
      "During handling of the above exception, another exception occurred:\n",
      "\n",
      "Traceback (most recent call last):\n",
      "  File \"C:\\ProgramData\\Anaconda3\\envs\\tf1\\lib\\site-packages\\IPython\\core\\interactiveshell.py\", line 2061, in showtraceback\n",
      "    stb = value._render_traceback_()\n",
      "AttributeError: 'TypeError' object has no attribute '_render_traceback_'\n",
      "\n",
      "During handling of the above exception, another exception occurred:\n",
      "\n",
      "Traceback (most recent call last):\n",
      "  File \"C:\\ProgramData\\Anaconda3\\envs\\tf1\\lib\\site-packages\\IPython\\core\\ultratb.py\", line 1101, in get_records\n",
      "    return _fixed_getinnerframes(etb, number_of_lines_of_context, tb_offset)\n",
      "  File \"C:\\ProgramData\\Anaconda3\\envs\\tf1\\lib\\site-packages\\IPython\\core\\ultratb.py\", line 248, in wrapped\n",
      "    return f(*args, **kwargs)\n",
      "  File \"C:\\ProgramData\\Anaconda3\\envs\\tf1\\lib\\site-packages\\IPython\\core\\ultratb.py\", line 281, in _fixed_getinnerframes\n",
      "    records = fix_frame_records_filenames(inspect.getinnerframes(etb, context))\n",
      "  File \"C:\\ProgramData\\Anaconda3\\envs\\tf1\\lib\\inspect.py\", line 1502, in getinnerframes\n",
      "    frameinfo = (tb.tb_frame,) + getframeinfo(tb, context)\n",
      "  File \"C:\\ProgramData\\Anaconda3\\envs\\tf1\\lib\\inspect.py\", line 1460, in getframeinfo\n",
      "    filename = getsourcefile(frame) or getfile(frame)\n",
      "  File \"C:\\ProgramData\\Anaconda3\\envs\\tf1\\lib\\inspect.py\", line 696, in getsourcefile\n",
      "    if getattr(getmodule(object, filename), '__loader__', None) is not None:\n",
      "  File \"C:\\ProgramData\\Anaconda3\\envs\\tf1\\lib\\inspect.py\", line 733, in getmodule\n",
      "    if ismodule(module) and hasattr(module, '__file__'):\n",
      "  File \"C:\\ProgramData\\Anaconda3\\envs\\tf1\\lib\\site-packages\\tensorflow\\__init__.py\", line 50, in __getattr__\n",
      "    module = self._load()\n",
      "  File \"C:\\ProgramData\\Anaconda3\\envs\\tf1\\lib\\site-packages\\tensorflow\\__init__.py\", line 44, in _load\n",
      "    module = _importlib.import_module(self.__name__)\n",
      "  File \"C:\\ProgramData\\Anaconda3\\envs\\tf1\\lib\\importlib\\__init__.py\", line 127, in import_module\n",
      "    return _bootstrap._gcd_import(name[level:], package, level)\n",
      "  File \"<frozen importlib._bootstrap>\", line 1006, in _gcd_import\n",
      "  File \"<frozen importlib._bootstrap>\", line 983, in _find_and_load\n",
      "  File \"<frozen importlib._bootstrap>\", line 965, in _find_and_load_unlocked\n",
      "ModuleNotFoundError: No module named 'tensorflow_core.estimator'\n",
      "Traceback (most recent call last):\n",
      "  File \"C:\\ProgramData\\Anaconda3\\envs\\tf1\\lib\\site-packages\\IPython\\core\\interactiveshell.py\", line 3441, in run_code\n",
      "    exec(code_obj, self.user_global_ns, self.user_ns)\n",
      "  File \"C:\\Users\\zarre\\AppData\\Local\\Temp/ipykernel_30824/2015509455.py\", line 1, in <module>\n",
      "    keras.models.load_model(\"Models/resnet18/saved_model.pb\")\n",
      "  File \"C:\\ProgramData\\Anaconda3\\envs\\tf1\\lib\\site-packages\\keras\\engine\\saving.py\", line 492, in load_wrapper\n",
      "    return load_function(*args, **kwargs)\n",
      "  File \"C:\\ProgramData\\Anaconda3\\envs\\tf1\\lib\\site-packages\\keras\\engine\\saving.py\", line 583, in load_model\n",
      "    with H5Dict(filepath, mode='r') as h5dict:\n",
      "  File \"C:\\ProgramData\\Anaconda3\\envs\\tf1\\lib\\site-packages\\keras\\utils\\io_utils.py\", line 191, in __init__\n",
      "    self.data = h5py.File(path, mode=mode)\n",
      "  File \"C:\\ProgramData\\Anaconda3\\envs\\tf1\\lib\\site-packages\\h5py\\_hl\\files.py\", line 445, in __init__\n",
      "    swmr=swmr)\n",
      "  File \"C:\\ProgramData\\Anaconda3\\envs\\tf1\\lib\\site-packages\\h5py\\_hl\\files.py\", line 195, in make_fid\n",
      "    fid = h5f.open(name, flags, fapl=fapl)\n",
      "  File \"h5py\\_objects.pyx\", line 54, in h5py._objects.with_phil.wrapper\n",
      "  File \"h5py\\_objects.pyx\", line 55, in h5py._objects.with_phil.wrapper\n",
      "  File \"h5py\\h5f.pyx\", line 96, in h5py.h5f.open\n",
      "OSError: Unable to open file (file signature not found)\n",
      "\n",
      "During handling of the above exception, another exception occurred:\n",
      "\n",
      "Traceback (most recent call last):\n",
      "  File \"C:\\ProgramData\\Anaconda3\\envs\\tf1\\lib\\site-packages\\IPython\\core\\interactiveshell.py\", line 2061, in showtraceback\n",
      "    stb = value._render_traceback_()\n",
      "AttributeError: 'OSError' object has no attribute '_render_traceback_'\n",
      "\n",
      "During handling of the above exception, another exception occurred:\n",
      "\n",
      "Traceback (most recent call last):\n",
      "  File \"C:\\ProgramData\\Anaconda3\\envs\\tf1\\lib\\site-packages\\IPython\\core\\interactiveshell.py\", line 3361, in run_ast_nodes\n",
      "    if (await self.run_code(code, result,  async_=asy)):\n",
      "  File \"C:\\ProgramData\\Anaconda3\\envs\\tf1\\lib\\site-packages\\IPython\\core\\interactiveshell.py\", line 3458, in run_code\n",
      "    self.showtraceback(running_compiled_code=True)\n",
      "  File \"C:\\ProgramData\\Anaconda3\\envs\\tf1\\lib\\site-packages\\IPython\\core\\interactiveshell.py\", line 2064, in showtraceback\n",
      "    value, tb, tb_offset=tb_offset)\n",
      "  File \"C:\\ProgramData\\Anaconda3\\envs\\tf1\\lib\\site-packages\\IPython\\core\\ultratb.py\", line 1368, in structured_traceback\n",
      "    self, etype, value, tb, tb_offset, number_of_lines_of_context)\n",
      "  File \"C:\\ProgramData\\Anaconda3\\envs\\tf1\\lib\\site-packages\\IPython\\core\\ultratb.py\", line 1268, in structured_traceback\n",
      "    self, etype, value, tb, tb_offset, number_of_lines_of_context\n",
      "  File \"C:\\ProgramData\\Anaconda3\\envs\\tf1\\lib\\site-packages\\IPython\\core\\ultratb.py\", line 1125, in structured_traceback\n",
      "    tb_offset)\n",
      "  File \"C:\\ProgramData\\Anaconda3\\envs\\tf1\\lib\\site-packages\\IPython\\core\\ultratb.py\", line 1082, in format_exception_as_a_whole\n",
      "    last_unique, recursion_repeat = find_recursion(orig_etype, evalue, records)\n",
      "  File \"C:\\ProgramData\\Anaconda3\\envs\\tf1\\lib\\site-packages\\IPython\\core\\ultratb.py\", line 382, in find_recursion\n",
      "    return len(records), 0\n",
      "TypeError: object of type 'NoneType' has no len()\n",
      "\n",
      "During handling of the above exception, another exception occurred:\n",
      "\n",
      "Traceback (most recent call last):\n",
      "  File \"C:\\ProgramData\\Anaconda3\\envs\\tf1\\lib\\site-packages\\IPython\\core\\interactiveshell.py\", line 2061, in showtraceback\n",
      "    stb = value._render_traceback_()\n",
      "AttributeError: 'TypeError' object has no attribute '_render_traceback_'\n",
      "\n",
      "During handling of the above exception, another exception occurred:\n",
      "\n",
      "Traceback (most recent call last):\n",
      "  File \"C:\\ProgramData\\Anaconda3\\envs\\tf1\\lib\\site-packages\\IPython\\core\\interactiveshell.py\", line 2944, in _run_cell\n",
      "    return runner(coro)\n",
      "  File \"C:\\ProgramData\\Anaconda3\\envs\\tf1\\lib\\site-packages\\IPython\\core\\async_helpers.py\", line 68, in _pseudo_sync_runner\n",
      "    coro.send(None)\n",
      "  File \"C:\\ProgramData\\Anaconda3\\envs\\tf1\\lib\\site-packages\\IPython\\core\\interactiveshell.py\", line 3170, in run_cell_async\n",
      "    interactivity=interactivity, compiler=compiler, result=result)\n",
      "  File \"C:\\ProgramData\\Anaconda3\\envs\\tf1\\lib\\site-packages\\IPython\\core\\interactiveshell.py\", line 3380, in run_ast_nodes\n",
      "    self.showtraceback()\n",
      "  File \"C:\\ProgramData\\Anaconda3\\envs\\tf1\\lib\\site-packages\\IPython\\core\\interactiveshell.py\", line 2064, in showtraceback\n",
      "    value, tb, tb_offset=tb_offset)\n",
      "  File \"C:\\ProgramData\\Anaconda3\\envs\\tf1\\lib\\site-packages\\IPython\\core\\ultratb.py\", line 1368, in structured_traceback\n",
      "    self, etype, value, tb, tb_offset, number_of_lines_of_context)\n",
      "  File \"C:\\ProgramData\\Anaconda3\\envs\\tf1\\lib\\site-packages\\IPython\\core\\ultratb.py\", line 1268, in structured_traceback\n",
      "    self, etype, value, tb, tb_offset, number_of_lines_of_context\n",
      "  File \"C:\\ProgramData\\Anaconda3\\envs\\tf1\\lib\\site-packages\\IPython\\core\\ultratb.py\", line 1143, in structured_traceback\n",
      "    chained_exceptions_tb_offset)\n",
      "  File \"C:\\ProgramData\\Anaconda3\\envs\\tf1\\lib\\site-packages\\IPython\\core\\ultratb.py\", line 1082, in format_exception_as_a_whole\n",
      "    last_unique, recursion_repeat = find_recursion(orig_etype, evalue, records)\n",
      "  File \"C:\\ProgramData\\Anaconda3\\envs\\tf1\\lib\\site-packages\\IPython\\core\\ultratb.py\", line 382, in find_recursion\n",
      "    return len(records), 0\n",
      "TypeError: object of type 'NoneType' has no len()\n",
      "\n",
      "During handling of the above exception, another exception occurred:\n",
      "\n",
      "Traceback (most recent call last):\n",
      "  File \"C:\\ProgramData\\Anaconda3\\envs\\tf1\\lib\\site-packages\\IPython\\core\\interactiveshell.py\", line 2061, in showtraceback\n",
      "    stb = value._render_traceback_()\n",
      "AttributeError: 'TypeError' object has no attribute '_render_traceback_'\n",
      "\n",
      "During handling of the above exception, another exception occurred:\n",
      "\n",
      "Traceback (most recent call last):\n",
      "  File \"C:\\ProgramData\\Anaconda3\\envs\\tf1\\lib\\site-packages\\IPython\\core\\ultratb.py\", line 1101, in get_records\n",
      "    return _fixed_getinnerframes(etb, number_of_lines_of_context, tb_offset)\n",
      "  File \"C:\\ProgramData\\Anaconda3\\envs\\tf1\\lib\\site-packages\\IPython\\core\\ultratb.py\", line 248, in wrapped\n",
      "    return f(*args, **kwargs)\n",
      "  File \"C:\\ProgramData\\Anaconda3\\envs\\tf1\\lib\\site-packages\\IPython\\core\\ultratb.py\", line 281, in _fixed_getinnerframes\n",
      "    records = fix_frame_records_filenames(inspect.getinnerframes(etb, context))\n",
      "  File \"C:\\ProgramData\\Anaconda3\\envs\\tf1\\lib\\inspect.py\", line 1502, in getinnerframes\n",
      "    frameinfo = (tb.tb_frame,) + getframeinfo(tb, context)\n",
      "  File \"C:\\ProgramData\\Anaconda3\\envs\\tf1\\lib\\inspect.py\", line 1460, in getframeinfo\n",
      "    filename = getsourcefile(frame) or getfile(frame)\n",
      "  File \"C:\\ProgramData\\Anaconda3\\envs\\tf1\\lib\\inspect.py\", line 696, in getsourcefile\n",
      "    if getattr(getmodule(object, filename), '__loader__', None) is not None:\n",
      "  File \"C:\\ProgramData\\Anaconda3\\envs\\tf1\\lib\\inspect.py\", line 733, in getmodule\n",
      "    if ismodule(module) and hasattr(module, '__file__'):\n",
      "  File \"C:\\ProgramData\\Anaconda3\\envs\\tf1\\lib\\site-packages\\tensorflow\\__init__.py\", line 50, in __getattr__\n",
      "    module = self._load()\n",
      "  File \"C:\\ProgramData\\Anaconda3\\envs\\tf1\\lib\\site-packages\\tensorflow\\__init__.py\", line 44, in _load\n",
      "    module = _importlib.import_module(self.__name__)\n",
      "  File \"C:\\ProgramData\\Anaconda3\\envs\\tf1\\lib\\importlib\\__init__.py\", line 127, in import_module\n",
      "    return _bootstrap._gcd_import(name[level:], package, level)\n",
      "  File \"<frozen importlib._bootstrap>\", line 1006, in _gcd_import\n",
      "  File \"<frozen importlib._bootstrap>\", line 983, in _find_and_load\n",
      "  File \"<frozen importlib._bootstrap>\", line 965, in _find_and_load_unlocked\n",
      "ModuleNotFoundError: No module named 'tensorflow_core.estimator'\n"
     ]
    }
   ],
   "metadata": {}
  }
 ],
 "metadata": {
  "orig_nbformat": 4,
  "language_info": {
   "name": "python",
   "version": "3.7.11",
   "mimetype": "text/x-python",
   "codemirror_mode": {
    "name": "ipython",
    "version": 3
   },
   "pygments_lexer": "ipython3",
   "nbconvert_exporter": "python",
   "file_extension": ".py"
  },
  "kernelspec": {
   "name": "python3",
   "display_name": "Python 3.7.11 64-bit ('tf1': conda)"
  },
  "interpreter": {
   "hash": "c9db8e131f8179849ccdf760cf16f1a16d37a0db3fd31d36f412cd434c1572a4"
  }
 },
 "nbformat": 4,
 "nbformat_minor": 2
}